Workbook

Sheet Legend
A1: Mask step
A3: Step from TI YMTC 232 L 3D NAND reverse-engineered flow
A5: Steps otherwise from TI SK hynix 176 L 3D NAND reverse-engineered flow
A7: Scaled by stack height

Sheet Materials (baseline)
Q1: # string stacking module: | R1: 0 | S1: 0 | T1: 0 | U1: 0 | V1: 1 | W1: 1 | X1: 1 | Y1: 2 | Z1: 4 | AA1: 5 | AB1: 6 | AC1: 7 | AD1: 8
A2: Module | B2: Seq# | C2: PFF# | D2: Process Description | E2: Recipe Description | F2: THK/Depth/CD | G2: Material | H2: Method | J2: Thickness/CD (nm) | K2: Material | L2: Geometry | M2: Volume (nm^3) | N2: Mass (g) | O2: gCO2e | Q2: # fabricated layers: | R2: 36 | S2: 60 | T2: 80 | U2: 108 | V2: 148 | W2: 196 | X2: 256 | Y2: 356 | Z2: 532 | AA2: 660 | AB2: 788 | AC2: 916 | AD2: 1044
A3: (1) WAFER PREP | G3: Si | K3: Wafer (Si) | N3: 0.0706 | O3: ='Reference Values'!D28 -> 26000
A4: (2) CuA PERIPHERY + ROUTING | B4: 6 | C4: 60 | D4: Nitride Deposition | E4: SiN, LPCVD | F4: 30 nm | G4: SiN | H4: LPCVD | J4: 242 | K4: SiN | L4: Wafer | M4: =J4*'Reference Values'!$C$2 -> 1.7106e+19 | N4: =M4*'Reference Values'!$C$19 -> 0.054225931 | O4: =N4*'Reference Values'!$D$19 -> 3.5014798
A5: (2) CuA PERIPHERY + ROUTING | B5: 7 | C5: 70 | D5: High Voltage Gate Oxide - Photo | E5: PR/ARC, KRF | F5: TPR=0.5 um | G5: PR/ARC | H5: KRF | J5: 31 | K5: SiON | L5: Wafer | M5: =J5*'Reference Values'!$C$2 -> 2.19126e+18 | N5: =M5*'Reference Values'!$C$21 -> 0.0061574431 | O5: =N5*'Reference Values'!$D$21 -> 0.23318584
A6: (2) CuA PERIPHERY + ROUTING | B6: 16 | C6: 160 | D6: Decoupled Plasma Nitridation | E6: SiON, PLASMA | F6: Top 1 nm | G6: SiON | H6: PLASMA | J6: 18600 | K6: PR/ARC | L6: Wafer | M6: =J6*'Reference Values'!$C$2 -> 1.31476e+21 | N6: =M6*'Reference Values'!$C$17 -> 1.2700548 | O6: =N6*'Reference Values'!$D$17 -> 5.3342302
A7: (2) CuA PERIPHERY + ROUTING | B7: 18 | C7: 180 | D7: Nitride Deposition | E7: SiN, LPCVD | F7: 50 nm | G7: SiN | H7: LPCVD | J7: 3434 | K7: SiO | L7: Wafer | M7: =J7*'Reference Values'!$C$2 -> 2.42735e+20 | N7: =M7*'Reference Values'!$C$20 -> 0.51702588 | O7: =N7*'Reference Values'!$D$20 -> 1.0580748
A8: (2) CuA PERIPHERY + ROUTING | B8: 19 | C8: 190 | D8: Deep N-Well IIP - Photo | E8: PR/ARC, I-LINE | F8: TPR=3.0 um | G8: PR/ARC | H8: I-LINE | J8: 500 | K8: ACL | L8: Wafer | M8: =J8*'Reference Values'!$C$2 -> 3.53429e+19 | N8: =M8*'Reference Values'!$C$8 -> 0.070685835 | O8: =N8*'Reference Values'!$D$8 -> 18
A9: (2) CuA PERIPHERY + ROUTING | B9: 24 | C9: 240 | D9: High Voltage N-Well IIP - Photo | E9: PR/ARC, I-LINE | F9: TPR=1.0 um | G9: PR/ARC | H9: I-LINE | J9: 23 | K9: Ti | L9: Wafer | M9: =J9*'Reference Values'!$C$2 -> 1.62577e+18 | N9: =M9*'Reference Values'!$C$24 -> 0.0073159839 | O9: =N9*'Reference Values'!$D$24 -> 0.34848485
A10: (2) CuA PERIPHERY + ROUTING | B10: 30 | C10: 300 | D10: High Voltage P-Well IIP - Photo | E10: PR/ARC, I-LINE | F10: TPR=1.0 um | G10: PR/ARC | H10: I-LINE | J10: 6 | K10: WN | L10: Wafer | M10: =J10*'Reference Values'!$C$2 -> 4.24115e+17 | N10: =M10*'Reference Values'!$C$29 -> 0.0075492471 | O10: =N10*'Reference Values'!$D$29 -> 0.58
A11: (2) CuA PERIPHERY + ROUTING | B11: 36 | C11: 360 | D11: Depletion NMOS IIP - Photo | E11: PR/ARC, I-LINE | F11: TPR=1.0 um | G11: PR/ARC | H11: I-LINE | J11: 3 | K11: WSiN | L11: Wafer | M11: =J11*'Reference Values'!$C$2 -> 2.12058e+17 | N11: =M11*'Reference Values'!$C$30 -> 0.0034141258 | O11: =N11*'Reference Values'!$D$30 -> 0.25
A12: (2) CuA PERIPHERY + ROUTING | B12: 40 | C12: 400 | D12: P-Well IIP - Photo | E12: PR/ARC, I-LINE | F12: TPR=1.0 um | G12: PR/ARC | H12: I-LINE | J12: 867 | K12: W | L12: Wafer | M12: =J12*'Reference Values'!$C$2 -> 6.12846e+19 | N12: =M12*'Reference Values'!$C$27 -> 1.1827931 | O12: =N12*'Reference Values'!$D$27 -> 89.673381
A13: (2) CuA PERIPHERY + ROUTING | B13: 46 | C13: 460 | D13: N-Well IIP - Photo | E13: PR/ARC, I-LINE | F13: TPR=1.0 um | G13: PR/ARC | H13: I-LINE | J13: 30 | K13: TIN | L13: Wafer | M13: =J13*'Reference Values'!$C$2 -> 2.12058e+18 | N13: =M13*'Reference Values'!$C$26 -> 0.011048196 | O13: =N13*'Reference Values'!$D$26 -> 0.48587571
A14: (2) CuA PERIPHERY + ROUTING | B14: 52 | C14: 520 | D14: Low Voltage NMOS VT2 Adjust IIP - Photo | E14: PR/ARC, I-LINE | F14: TPR=0.5 um | G14: PR/ARC | H14: I-LINE
A15: (2) CuA PERIPHERY + ROUTING | B15: 56 | C15: 560 | D15: Low Volatge PMOS VT2 Adjust IIP - Photo | E15: PR/ARC, I-LINE | F15: TPR=0.5 um | G15: PR/ARC | H15: I-LINE
A16: (2) CuA PERIPHERY + ROUTING | B16: 60 | C16: 600 | D16: Active - Photo | E16: PR/ARC, ARF | F16: TPR=1.0 um | G16: PR/ARC | H16: ARF
A17: (2) CuA PERIPHERY + ROUTING | B17: 66 | C17: 660 | D17: Offset Junction IIP - Photo | E17: PR/ARC, I-LINE | F17: TPR=0.5 um | G17: PR/ARC | H17: I-LINE
A18: (2) CuA PERIPHERY + ROUTING | B18: 71 | C18: 710 | D18: Field IIP - Photo | E18: PR/ARC, I-LINE | F18: TPR=1.0 um | G18: PR/ARC | H18: I-LINE
A19: (2) CuA PERIPHERY + ROUTING | B19: 77 | C19: 770 | D19: STI Oxide | E19: SiO, HDP | F19: 900 nm | G19: SiO | H19: HDP
A20: (2) CuA PERIPHERY + ROUTING | B20: 88 | C20: 880 | D20: Nitride HM Deposition | E20: SiN, LPCVD | F20: 3 nm | G20: SiN | H20: LPCVD
A21: (2) CuA PERIPHERY + ROUTING | B21: 89 | C21: 890 | D21: Oxide HM Deposition | E21: SiO, PECVD | F21: 85 nm | G21: SiO | H21: PECVD
A22: (2) CuA PERIPHERY + ROUTING | B22: 90 | C22: 900 | D22: Poly Resistor - Photo | E22: PR/ARC, KRF | F22: TPR=0.5 um | G22: PR/ARC | H22: KRF
A23: (2) CuA PERIPHERY + ROUTING | B23: 96 | C23: 960 | D23: Peripheral Gate - Photo | E23: PR/ARC, ARF | F23: TPR=0.5 um | G23: PR/ARC | H23: ARF
A24: (2) CuA PERIPHERY + ROUTING | B24: 103 | C24: 1040 | D24: NMOS LDD IIP - Photo | E24: PR/ARC, KRF | F24: TPR=0.5 um | G24: PR/ARC | H24: KRF
A25: (2) CuA PERIPHERY + ROUTING | B25: 108 | C25: 1090 | D25: PMOS LDD IIP - Photo | E25: PR/ARC, KRF | F25: TPR=0.5 um | G25: PR/ARC | H25: KRF
... A57: (2) CuA PERIPHERY + ROUTING | B57: 185 | C57: 1860 | D57: W Deposition | E57: W, CVD | F57: 350 nm | G57: W | H57: CVD
A58: 3) DWB CMOS WAFER | B58: 133 | C58: 1330 | D58: TiN Liner Deposition | E58: TiN, CVD | F58: 7 nm | G58: TiN | H58: CVD | J58: =21+40+3 -> 64 | K58: TiN | L58: Wafer | M58: =J58*'Reference Values'!$C$2 -> 4.52389e+18 | N58: =M58*'Reference Values'!$C$26 -> 0.023569485 | O58: =N58*'Reference Values'!$D$26 -> 1.0365348
A59: 3) DWB CMOS WAFER | B59: 134 | C59: 1340 | D59: W Deposition | E59: W, CVD | F59: 100 nm | G59: W | H59: CVD | J59: =100+300+400 -> 800 | K59: W | L59: Wafer | M59: =J59*'Reference Values'!$C$2 -> 5.65487e+19 | N59: =M59*'Reference Values'!$C$27 -> 1.0913893 | O59: =N59*'Reference Values'!$D$27 -> 82.743604
A60: 3) DWB CMOS WAFER | B60: 142 | C60: 1420 | D60: TiN Liner Deposition | E60: TiN, CVD | F60: 3 nm | G60: TiN | H60: CVD | K60: Ta | L60: Wafer | M60: =J60*'Reference Values'!$C$2 -> 0
A61: 3) DWB CMOS WAFER | B61: 143 | C61: 1430 | D61: W Deposition | E61: W, CVD | F61: 150 nm | G61: W | H61: CVD | J61: =15*3+10 -> 55 | K61: TaN | L61: Wafer | M61: =J61*'Reference Values'!$C$2 -> 3.88772e+18 | N61: =M61*'Reference Values'!$C$22 -> 0.053261776 | O61: =N61*'Reference Values'!$D$22 -> 1.375
A62: 3) DWB CMOS WAFER | B62: 155 | C62: 1550 | D62: TiN Liner Deposition | E62: TiN, CVD | F62: 7 nm | G62: TiN | H62: CVD | J62: =500+900+500+150 -> 2050 | K62: Cu | L62: Wafer | M62: =J62*'Reference Values'!$C$2 -> 1.44906e+20 | N62: =M62*'Reference Values'!$C$13 -> 1.2983574 | O62: =N62*'Reference Values'!$D$13 -> 7.9071429
A63: 3) DWB CMOS WAFER | B63: 156 | C63: 1560 | D63: W Deposition | E63: W, CVD | F63: 150 nm | G63: W | H63: CVD | J63: 1444 | K63: SiN | L63: Wafer | M63: =J63*'Reference Values'!$C$2 -> 1.0207e+20 | N63: =M63*'Reference Values'!$C$19 -> 0.32356299 | O63: =N63*'Reference Values'!$D$19 -> 20.893127
A64: 3) DWB CMOS WAFER | B64: 164 | C64: 1640 | D64: TiN Liner Deposition | E64: TiN, CVD | F64: 7 nm | G64: TiN | H64: CVD | J64: 21500 | K64: PR/ARC | L64: Wafer | M64: =J64*'Reference Values'!$C$2 -> 1.51975e+21 | N64: =M64*'Reference Values'!$C$17 -> 1.4680741 | O64: =N64*'Reference Values'!$D$17 -> 6.1659112
A65: 3) DWB CMOS WAFER | B65: 165 | C65: 1650 | D65: W Deposition | E65: W, CVD | F65: 100 nm | G65: W | H65: CVD | J65: 3809 | K65: SiO | L65: Wafer | M65: =J65*'Reference Values'!$C$2 -> 2.69242e+20 | N65: =M65*'Reference Values'!$C$20 -> 0.57348619 | O65: =N65*'Reference Values'!$D$20 -> 1.1736188
A66: 3) DWB CMOS WAFER | B66: 173 | C66: 1730 | D66: Barrier & Seed Deposition | E66: Ta, TaN, Cu, PVD, ALD, PVD | F66: Bottom TaN: 15nm, S/W TaN: 15 nm | G66: Ta, TaN, Cu | H66: PVD, ALD, PVD | J66: =15+15+15+10 -> 55 | K66: SiON | L66: Wafer | M66: =J66*'Reference Values'!$C$2 -> 3.88772e+18 | N66: =M66*'Reference Values'!$C$21 -> 0.010924496 | O66: =N66*'Reference Values'!$D$21 -> 0.41371681
A67: 3) DWB CMOS WAFER | B67: 174 | C67: 1740 | D67: Cu Plate | E67: Cu, PLATE | F67: 150 nm | G67: Cu | H67: PLATE | J67: 130 | K67: Poly-Si | L67: Wafer | M67: =J67*'Reference Values'!$C$2 -> 9.18916e+18 | N67: =M67*'Reference Values'!$C$16 -> 0.021410739 | O67: =N67*'Reference Values'!$D$16 -> 0.088446727
A68: 3) DWB CMOS WAFER | B68: 190 | C68: 1900 | D68: Barrier & Seed Deposition | E68: Ta, TaN, Cu, PVD, ALD, PVD | F68: Bottom TaN: 15nm, S/W TaN: 15 nm | G68: Ta, TaN, Cu | H68: PVD, ALD, PVD | J68: 123 | K68: SiCN | L68: Wafer | M68: =J68*'Reference Values'!$C$2 -> 8.69436e+18 | N68: =M68*'Reference Values'!$C$18 -> 0.028952211 | O68: =N68*'Reference Values'!$D$18 -> 1.968
A69: 3) DWB CMOS WAFER | B69: 191 | C69: 1910 | D69: Cu Plate | E69: Cu, PLATE | F69: 500 nm | G69: Cu | H69: PLATE | J69: =26 -> 26 | K69: NiPt | L69: Wafer | M69: =J69*'Reference Values'!$C$2 -> 1.83783e+18 | N69: =M69*'Reference Values'!$C$15 -> 0.03418367 | O69: =N69*'Reference Values'!$D$15 -> 651.31313
A70: 3) DWB CMOS WAFER | B70: 207 | C70: 2070 | D70: Barrier & Seed Deposition | E70: Ta, TaN, Cu, PVD, ALD, PVD | F70: Bottom TaN: 15nm, S/W TaN: 15 nm | G70: Ta, TaN, Cu | H70: PVD, ALD, PVD
A71: 3) DWB CMOS WAFER | B71: 208 | C71: 2080 | D71: Cu Plate | E71: Cu, PLATE | F71: 900 nm | G71: Cu | H71: PLATE
...

Sheet Mo
A1: MOLYBDENUM
B2: Thickness/CD (nm) | C2: Material | D2: Geometry | E2: Volume (nm^3) | F2: Mass (g) | G2: gCO2e | P2: gCO23/layer
A3: (10) SLIT FORMATION AND WL METAL REPLACEMENT | B3: 10000 | C3: PR/ARC | D3: Wafer | E3: =B3*'Reference Values'!$C$2 -> 7.06858e+20 | F3: =E3*'Reference Values'!$C$17 -> 0.68282516 | G3: =F3*'Reference Values'!$D$17 -> 2.8678657
A4: (10) SLIT FORMATION AND WL METAL REPLACEMENT | B4: 2 | C4: AlO | D4: Wafer | E4: =B4*'Reference Values'!$C$2 -> 1.41372e+17 | F4: =E4*'Reference Values'!$C$11 -> 0.00056407296 | G4: =F4*'Reference Values'!$D$11 -> 0.00083636364 | P4: =SUM(G4:G6)/196 -> 0.0014179152 | R4: =$P$4*'Materials (baseline)'!R2 -> 0.051044946 | S4: =$P$4*'Materials (baseline)'!S2 -> 0.08507491 | T4: =$P$4*'Materials (baseline)'!T2 -> 0.11343321 | U4: =$P$4*'Materials (baseline)'!U2 -> 0.15313484 | V4: =$P$4*'Materials (baseline)'!V2 -> 0.20985144 | W4: =$P$4*'Materials (baseline)'!W2 -> 0.27791137 | X4: =$P$4*'Materials (baseline)'!X2 -> 0.36298628 | Y4: =$P$4*'Materials (baseline)'!Y2 -> 0.5047778 | ... AD4: =$P$4*'Materials (baseline)'!AD2 -> 1.4803034
A5: (10) SLIT FORMATION AND WL METAL REPLACEMENT | B5: 2.5 | C5: TiN | D5: Wafer | E5: =B5*'Reference Values'!$C$2 -> 1.76715e+17 | F5: =E5*'Reference Values'!$C$26 -> 0.000920683 | G5: =F5*'Reference Values'!$D$26 -> 0.040489642
A6: (10) SLIT FORMATION AND WL METAL REPLACEMENT | B6: 20 | C6: Mo | D6: Wafer | E6: =B6*'Reference Values'!$C$2 -> 1.41372e+18 | F6: =E6*'Reference Values'!$C$14 -> 0.01441991 | G6: =F6*'Reference Values'!$D$14 -> 0.23658537
A7: (10) SLIT FORMATION AND WL METAL REPLACEMENT | B7: 45 | C7: SiO | D7: Wafer | E7: =B7*'Reference Values'!$C$2 -> 3.18086e+18 | F7: =E7*'Reference Values'!$C$20 -> 0.0067752373 | G7: =F7*'Reference Values'!$D$20 -> 0.013865278
A8: (10) SLIT FORMATION AND WL METAL REPLACEMENT | B8: 140 | C8: Poly-Si | D8: Wafer | E8: =B8*'Reference Values'!$C$2 -> 9.89602e+18 | F8: =E8*'Reference Values'!$C$16 -> 0.023057719 | G8: =F8*'Reference Values'!$D$16 -> 0.095250321 | O8: =SUM(G7:G8,G3) -> 2.9769813 | R8: =$O$8+R4 -> 3.0280262 | S8: =$O$8+S4 -> 3.0620562 | T8: =$O$8+T4 -> 3.0904145 | U8: =$O$8+U4 -> 3.1301161 | V8: =$O$8+V4 -> 3.1868327 | W8: =$O$8+W4 -> 3.2548927 | X8: =$O$8+X4 -> 3.3399676 | Y8: =$O$8+Y4 -> 3.4817591 | ... AD8: =$O$8+AD4 -> 4.4572847

Sheet Cryo
Q1: Cryo string stacking modules: | R1: 0 | S1: 0 | T1: 0 | U1: 0 | V1: 0 | W1: 0 | X1: 1 | Y1: 1 | Z1: 2 | AA1: 2 | AB1: 3 | AC1: 3 | AD1: 4
A2: Module | B2: Seq# | C2: PFF# | D2: Process Description | E2: Recipe Description | F2: THK/Depth/CD | G2: Material | H2: Method | J2: Thickness/CD (nm) | K2: Material | L2: Geometry | M2: Volume (nm^3) | N2: Mass (g) | O2: gCO2e
A3: CRYO
A4: (7) STRING STACKING | B4: 551 | C4: 2320 | D4: TiN Deposition | E4: TiN, CVD | F4: 70 nm | G4: TiN | H4: CVD | J4: =70 -> 70 | K4: TiN | M4: =J4*'Reference Values'!$C$2 -> 4.94801e+18 | N4: =M4*'Reference Values'!$C$26 -> 0.025779124 | O4: =N4*'Reference Values'!$D$26 -> 1.13371 | Q4: MODULE TOTAL --> | R4: =$O$4*R1 -> 0 | S4: =$O$4*S1 -> 0 | T4: =$O$4*T1 -> 0 | U4: =$O$4*U1 -> 0 | V4: =$O$4*V1 -> 0 | W4: =$O$4*W1 -> 0 | X4: =$O$4*X1 -> 1.13371 | Y4: =$O$4*Y1 -> 1.13371 | ... AD4: =$O$4*AD1 -> 4.5348399

Sheet Reference Values
A1: Area of 300 mm wafer (cm^2): | C1: =(15)^2*PI() -> 706.85835
A2: Area of 300 mm wafer (nm^2): | C2: =(1.5*10^8)^2*PI() -> 7.06858e+16
A6: Material | B6: Densities (g/cm3) | C6: Densities (g/nm3) | D6: To calculate embodied carbon (gCO2e/g):
A7: a-Si (amorphous silicon) | B7: 2.29 | C7: =B7*(10^-21) -> 0 | D7: 308.88878
A8: ACL (amorphous carbon layer) | B8: 2 | C8: =B8*(10^-21) -> 0 | D8: 254.64791
A9: Al (aluminum) | B9: 2.7 | C9: =B9*(10^-21) -> 0 | D9: 10.726881
A10: Al(Cu) (aluminum-copper alloy, assumed 50/50) | B10: =AVERAGE(B9,B13) -> 5.83 | C10: =B10*(10^-21) -> 0 | D10: =AVERAGE(D9,D13) -> 8.4084969
A11: AlO (aluminum oxide) | B11: 3.99 | C11: =B11*(10^-21) -> 0 | D11: 1.4827224
A12: CHM (carbon-based hard mask) | B12: 2.2 | C12: =B12*(10^-21) -> 0 | D12: 13.986343
A13: Cu (copper) | B13: 8.96 | C13: =B13*(10^-21) -> 0 | D13: 6.0901126
A14: Mo (molybdenum) | B14: 10.2 | C14: =B14*(10^-21) -> 0 | D14: 16.406854
A15: NiPt (nickel platinum) | B15: 18.6 | C15: =B15*(10^-21) -> 0 | D15: 19053.341
A16: Poly-Si (polycrystalline silicon) | B16: 2.33 | C16: =B16*(10^-21) -> 0 | D16: 4.1309515
A17: PR/ARC (as PGMEA) (photoresist/anti-reflective coating( | B17: 0.966 | C17: =B17*(10^-21) -> 0 | D17: 4.2
A18: SiCN (silicon carbon nitride) | B18: 3.33 | C18: =B18*(10^-21) -> 0 | D18: 67.974083
A19: SiN (silicon nitride) | B19: 3.17 | C19: =B19*(10^-21) -> 0 | D19: 64.572054
A20: SiO (silicon oxide) | B20: 2.13 | C20: =B20*(10^-21) -> 0 | D20: 2.0464639
A21: SiON (silicon oxynitride) | B21: 2.81 | C21: =B21*(10^-21) -> 0 | D21: 37.870564
A22: TaN (tantalum nitride) | B22: 13.7 | C22: =B22*(10^-21) -> 0 | D22: 25.815887
... A24: Ti (titanium) | B24: 4.5 | C24: =B24*(10^-21) -> 0 | D24: 47.633354
A25: Ti(Al) (titanium-aluminum alloy, assumed 50/50) | B25: =AVERAGE(B24,B9) -> 3.6 | C25: =B25*(10^-21) -> 0 | D25: =AVERAGE(D24,D9) -> 29.180117
A26: TiN (titanium nitride) | B26: 5.21 | C26: =B26*(10^-21) -> 0 | D26: 43.977832
A27: W (tungsten) | B27: 19.3 | C27: =B27*(10^-21) -> 0 | D27: 75.814931
A28: Wafer (silicon, 300 mm diameter) | B28: N/A (1 wafer) | C28: N/A | D28: =26*1000 -> 26000 | E28: (per wafer)
A29: WN (tungsten nitride) | B29: 17.8 | C29: =B29*(10^-21) -> 0 | D29: 76.828853
A30: WSiN (tungsten silicon nitride) | B30: 16.1 | C30: =B30*(10^-21) -> 0 | D30: 73.225187

Sheet Mo W comparison
A1: Material from module 10, 176L | B1: Tungsten WL (gCO2e) | C1: Mo WL (gCO2e)
A2: PR/ARC | B2: 2.8678657 | C2: 2.8678657
A3: AlO | B3: 0.00083636364 | C3: 0.00083636364
A4: TiN | B4: 0.040489642 | C4: 0.040489642
A5: W | B5: 2.0685901 | C5: 0.23658537
A6: SiO | B6: 0.013865278 | C6: 0.013865278
A7: Poly-Si | B7: 0.095250321 | C7: 0.095250321
